2024-12-25 07:49:30,920 - __main__ - ERROR - An error occurred
Traceback (most recent call last):
  File "/tmp/ipykernel_5805/2858173309.py", line 7, in <module>
    1 / 0
ZeroDivisionError: division by zero
